Workbook

Sheet NAICS HOURLY INCOME
A1: CNS01 | B1: CNS02 | C1: CNS03 | D1: CNS04 | E1: CNS05 | F1: CNS06 | G1: CNS07 | H1: CNS08 | I1: CNS09 | J1: CNS10 | K1: CNS11 | L1: CNS12 | M1: CNS13 | N1: CNS14 | O1: CNS15 | P1: CNS16 | Q1: CNS17 | R1: CNS18 | S1: CNS19 | T1: CNS20 | U1: Year | V1: Area Title | W1: MSA Code
A2: 9.38 | B2: 21.73 | C2: 29.22 | D2: 19.15 | E2: 17.46 | F2: 18.29 | G2: 10.7 | H2: 18.81 | I2: 24.17 | J2: 20.65 | K2: 14.98 | L2: 27.07 | M2: 26.78 | N2: 12.67 | O2: 20.73 | P2: 16.33 | Q2: 11.22 | R2: 9.05 | S2: 13.24 | T2: 21.97 | U2: 2010 | V2: National
A3: 9.36 | B3: 22.16 | C3: 30.1 | D3: 19.56 | E3: 17.78 | F3: 18.61 | G3: 10.88 | H3: 19.31 | I3: 24.93 | J3: 21.35 | K3: 15.3 | L3: 27.87 | M3: 27.84 | N3: 12.8 | O3: 21.03 | P3: 16.73 | Q3: 11.29 | R3: 9.14 | S3: 13.38 | T3: 22.37 | U3: 2011 | V3: National
A4: 9.4 | B4: 22.87 | C4: 30.72 | D4: 19.86 | E4: 17.98 | F4: 18.86 | G4: 10.94 | H4: 19.43 | I4: 25.57 | J4: 21.78 | K4: 15.52 | L4: 28.43 | M4: 28.52 | N4: 12.74 | O4: 21.1 | P4: 16.94 | Q4: 11.39 | R4: 9.18 | S4: 13.54 | T4: 22.58 | U4: 2012 | V4: National
A5: 9.43 | B5: 23.07 | C5: 31.75 | D5: 20.11 | E5: 18.12 | F5: 19.08 | G5: 11.05 | H5: 19.29 | I5: 26.12 | J5: 22.3 | K5: 15.83 | L5: 29 | M5: 29.08 | N5: 12.96 | O5: 21.22 | P5: 17.16 | Q5: 11.49 | R5: 9.22 | S5: 13.69 | T5: 22.87 | U5: 2013 | V5: National
A6: 9.7 | B6: 23.56 | C6: 32.78 | D6: 20.36 | E6: 18.34 | F6: 19.29 | G6: 11.19 | H6: 19.48 | I6: 26.81 | J6: 22.86 | K6: 16.28 | L6: 29.45 | M6: 29.91 | N6: 13.15 | O6: 21.51 | P6: 17.38 | Q6: 11.68 | R6: 9.3 | S6: 13.99 | T6: 23.49 | U6: 2014 | V6: National
A7: 10.52 | B7: 23.83 | C7: 33.66 | D7: 20.84 | E7: 18.61 | F7: 19.7 | G7: 11.38 | H7: 19.31 | I7: 27.82 | J7: 23.6 | K7: 16.74 | L7: 30.12 | M7: 30.59 | N7: 13.43 | O7: 21.89 | P7: 17.72 | Q7: 11.99 | R7: 9.49 | S7: 14.3 | T7: 23.83 | U7: 2015 | V7: National
A8: 11.36 | B8: 25.13 | C8: 34.76 | D8: 21.46 | E8: 19 | F8: 20.23 | G8: 11.66 | H8: 19.4 | I8: 28.55 | J8: 24.41 | K8: 17.24 | L8: 30.82 | M8: 31.43 | N8: 13.88 | O8: 22.46 | P8: 18.11 | Q8: 12.3 | R8: 10.01 | S8: 14.69 | T8: 24.36 | U8: 2016 | V8: National
A9: 11.77 | B9: 24.84 | C9: 35.55 | D9: 22.03 | E9: 19.36 | F9: 20.63 | G9: 11.96 | H9: 19.69 | I9: 29.51 | J9: 25.1 | K9: 17.71 | L9: 31.43 | M9: 32.06 | N9: 14.28 | O9: 22.88 | P9: 18.16 | Q9: 12.66 | R9: 10.57 | S9: 15.03 | T9: 24.85 | U9: 2017 | V9: National
A10: 12.26 | B10: 25.04 | C10: 36.49 | D10: 22.73 | E10: 19.88 | F10: 21.07 | G10: 12.4 | H10: 20.17 | I10: 30.49 | J10: 25.89 | K10: 18.41 | L10: 32.32 | M10: 33.18 | N10: 14.84 | O10: 23.48 | P10: 18.56 | Q10: 13.19 | R10: 11.12 | S10: 15.59 | T10: 25.57 | U10: 2018 | V10: National
A11: 13.18 | B11: 25.44 | C11: 37.5 | D11: 23.57 | E11: 20.46 | F11: 21.72 | G11: 13.16 | H11: 20.58 | I11: 31.66 | J11: 27.01 | K11: 19.02 | L11: 33.5 | M11: 34.23 | N11: 15.48 | O11: 24.11 | P11: 18.99 | Q11: 13.88 | R11: 11.64 | S11: 16.33 | T11: 26.21 | U11: 2019 | V11: National
A12: 14.43 | B12: 26.41 | C12: 38.77 | D12: 24.26 | E12: 21.2 | F12: 22.51 | G12: 13.97 | H12: 20.96 | I12: 34.2 | J12: 28.04 | K12: 19.69 | L12: 34.86 | M12: 35.61 | N12: 16.29 | O12: 24.85 | P12: 19.6 | Q12: 14.72 | R12: 12.19 | S12: 17.5 | T12: 27.22 | U12: 2020 | V12: National
A13: 14.43 | B13: 28.81 | C13: 39.53 | D13: 23.59 | E13: 22.51 | F13: 22.97 | G13: 14.36 | H13: 22.47 | I13: 37.02 | J13: 29.44 | K13: 21.36 | L13: 36.98 | M13: 37.38 | N13: 17.48 | O13: 24.1 | P13: 20.23 | Q13: 14.7 | R13: 13.69 | S13: 18.02 | T13: 28.91 | U13: 2021 | V13: National
A14: 16.36 | B14: 28.5 | C14: 44.23 | D14: 26.22 | E14: 22.89 | F14: 23.94 | G14: 15.99 | H14: 22.8 | I14: 38.45 | J14: 30.42 | K14: 22.21 | L14: 37.77 | M14: 38.71 | N14: 17.75 | O14: 26.49 | P14: 21.59 | Q14: 16.72 | R14: 14.31 | S14: 18.88 | T14: 29.36 | U14: 2022 | V14: National
A15: =A2*Index!$D$14 -> 12.346008 | B15: =B2*Index!$D$14 -> 28.601146 | C15: =C2*Index!$D$14 -> 38.459526 | D15: =D2*Index!$D$14 -> 25.205336 | E15: =E2*Index!$D$14 -> 22.980949 | F15: =F2*Index!$D$14 -> 24.073399 | G15: =G2*Index!$D$14 -> 14.083399 | H15: =H2*Index!$D$14 -> 24.757826 | ... T15: =T2*Index!$D$14 -> 28.917036 | U15: 2010 | V15: New York-Newark-Jersey City, NY-NJ-PA | W15: 35620
A16: =A3*Index!$D$13 -> 12.326624 | B16: =B3*Index!$D$13 -> 29.183545 | C16: =C3*Index!$D$13 -> 39.640103 | D16: =D3*Index!$D$13 -> 25.759483 | E16: =E3*Index!$D$13 -> 23.415317 | F16: =F3*Index!$D$13 -> 24.508383 | G16: =G3*Index!$D$13 -> 14.328383 | H16: =H3*Index!$D$13 -> 25.430246 | ... T16: =T3*Index!$D$13 -> 29.460103 | U16: 2011 | V16: New York-Newark-Jersey City, NY-NJ-PA | W16: 35620
A17: =A4*Index!$D$12 -> 12.326982 | B17: =B4*Index!$D$12 -> 29.991285 | C17: =C4*Index!$D$12 -> 40.285627 | D17: =D4*Index!$D$12 -> 26.044028 | E17: =E4*Index!$D$12 -> 23.578632 | F17: =F4*Index!$D$12 -> 24.732647 | G17: =G4*Index!$D$12 -> 14.346509 | H17: =H4*Index!$D$12 -> 25.480134 | ... T17: =T4*Index!$D$12 -> 29.610985 | U17: 2012 | V17: New York-Newark-Jersey City, NY-NJ-PA | W17: 35620
A18: =A5*Index!$D$11 -> 12.382828 | B18: =B5*Index!$D$11 -> 30.293939 | C18: =C5*Index!$D$11 -> 41.691919 | D18: =D5*Index!$D$11 -> 26.407071 | E18: =E5*Index!$D$11 -> 23.793939 | F18: =F5*Index!$D$11 -> 25.054545 | G18: =G5*Index!$D$11 -> 14.510101 | H18: =H5*Index!$D$11 -> 25.330303 | ... T18: =T5*Index!$D$11 -> 30.031313 | U18: 2013 | V18: New York-Newark-Jersey City, NY-NJ-PA | W18: 35620
A19: =A6*Index!$D$10 -> 12.661878 | B19: =B6*Index!$D$10 -> 30.754005 | C19: =C6*Index!$D$10 -> 42.789316 | D19: =D6*Index!$D$10 -> 26.576891 | E19: =E6*Index!$D$10 -> 23.940087 | F19: =F6*Index!$D$10 -> 25.180168 | G19: =G6*Index!$D$10 -> 14.606847 | H19: =H6*Index!$D$10 -> 25.428184 | ... T19: =T6*Index!$D$10 -> 30.662631 | U19: 2014 | V19: New York-Newark-Jersey City, NY-NJ-PA | W19: 35620
A20: =A7*Index!$D$9 -> 13.58246 | B20: =B7*Index!$D$9 -> 30.767113 | C20: =C7*Index!$D$9 -> 43.458709 | D20: =D7*Index!$D$9 -> 26.906699 | E20: =E7*Index!$D$9 -> 24.027527 | F20: =F7*Index!$D$9 -> 25.434836 | G20: =G7*Index!$D$9 -> 14.692814 | H20: =H7*Index!$D$9 -> 24.931303 | ... T20: =T7*Index!$D$9 -> 30.767113 | U20: 2015 | V20: New York-Newark-Jersey City, NY-NJ-PA | W20: 35620
A21: =A8*Index!$D$8 -> 14.665463 | B21: =B8*Index!$D$8 -> 32.442173 | C21: =C8*Index!$D$8 -> 44.874252 | D21: =D8*Index!$D$8 -> 27.704299 | E21: =E8*Index!$D$8 -> 24.528504 | F21: =F8*Index!$D$8 -> 26.116401 | G21: =G8*Index!$D$8 -> 15.052755 | H21: =H8*Index!$D$8 -> 25.044893 | ... T21: =T8*Index!$D$8 -> 31.448124 | U21: 2016 | V21: New York-Newark-Jersey City, NY-NJ-PA | W21: 35620
A22: =A9*Index!$D$7 -> 15.12894 | B22: =B9*Index!$D$7 -> 31.928876 | C22: =C9*Index!$D$7 -> 45.695312 | D22: =D9*Index!$D$7 -> 28.316954 | E22: =E9*Index!$D$7 -> 24.884985 | F22: =F9*Index!$D$7 -> 26.51742 | G22: =G9*Index!$D$7 -> 15.373162 | H22: =H9*Index!$D$7 -> 25.309161 | ... T22: =T9*Index!$D$7 -> 31.94173 | U22: 2017 | V22: New York-Newark-Jersey City, NY-NJ-PA | W22: 35620
A23: =A10*Index!$D$6 -> 15.708342 | B23: =B10*Index!$D$6 -> 32.082943 | C23: =C10*Index!$D$6 -> 46.753458 | D23: =D10*Index!$D$6 -> 29.123214 | E23: =E10*Index!$D$6 -> 25.471602 | F23: =F10*Index!$D$6 -> 26.99631 | G23: =G10*Index!$D$6 -> 15.887719 | H23: =H10*Index!$D$6 -> 25.843169 | ... T23: =T10*Index!$D$6 -> 32.762015 | U23: 2018 | V23: New York-Newark-Jersey City, NY-NJ-PA | W23: 35620
A24: =A11*Index!$D$5 -> 16.957063 | B24: =B11*Index!$D$5 -> 32.730477 | C24: =C11*Index!$D$5 -> 48.246575 | D24: =D11*Index!$D$5 -> 30.324581 | E24: =E11*Index!$D$5 -> 26.323332 | F24: =F11*Index!$D$5 -> 27.944416 | G24: =G11*Index!$D$5 -> 16.931332 | H24: =H11*Index!$D$5 -> 26.477721 | ... T24: =T11*Index!$D$5 -> 33.72114 | U24: 2019 | V24: New York-Newark-Jersey City, NY-NJ-PA | W24: 35620
A25: =A12*Index!$D$4 -> 18.806373 | B25: =B12*Index!$D$4 -> 34.419703 | C25: =C12*Index!$D$4 -> 50.52828 | D25: =D12*Index!$D$4 -> 31.617645 | E25: =E12*Index!$D$4 -> 27.629599 | F25: =F12*Index!$D$4 -> 29.336899 | G25: =G12*Index!$D$4 -> 18.206863 | H25: =H12*Index!$D$4 -> 27.316811 | ... T25: =T12*Index!$D$4 -> 35.475362 | U25: 2020 | V25: New York-Newark-Jersey City, NY-NJ-PA | W25: 35620
A26: =A13*Index!$D$3 -> 20.408904 | B26: =B13*Index!$D$3 -> 40.74709 | C26: =C13*Index!$D$3 -> 55.908798 | D26: =D13*Index!$D$3 -> 33.364244 | E26: =E13*Index!$D$3 -> 31.836758 | F26: =F13*Index!$D$3 -> 32.487354 | G26: =G13*Index!$D$3 -> 20.3099 | H26: =H13*Index!$D$3 -> 31.780185 | ... T26: =T13*Index!$D$3 -> 40.888524 | U26: 2021 | V26: New York-Newark-Jersey City, NY-NJ-PA | W26: 35620
A27: =A14*Index!$D$2 -> 21.072474 | B27: =B14*Index!$D$2 -> 36.709384 | C27: =C14*Index!$D$2 -> 56.970387 | D27: =D14*Index!$D$2 -> 33.772633 | E27: =E14*Index!$D$2 -> 29.483431 | F27: =F14*Index!$D$2 -> 30.835882 | G27: =G14*Index!$D$2 -> 20.595896 | H27: =H14*Index!$D$2 -> 29.367507 | ... T27: =T14*Index!$D$2 -> 37.817106 | U27: 2022 | V27: New York-Newark-Jersey City, NY-NJ-PA | W27: 35620

Sheet NAICS ANNUAL INCOME
A1: CNS01 | B1: CNS02 | C1: CNS03 | D1: CNS04 | E1: CNS05 | F1: CNS06 | G1: CNS07 | H1: CNS08 | I1: CNS09 | J1: CNS10 | K1: CNS11 | L1: CNS12 | M1: CNS13 | N1: CNS14 | O1: CNS15 | P1: CNS16 | Q1: CNS17 | R1: CNS18 | S1: CNS19 | T1: CNS20 | U1: Year | V1: Area Title | W1: MSA Code
A2: ='NAICS HOURLY INCOME'!A2*2080 -> 19510.4 | B2: ='NAICS HOURLY INCOME'!B2*2080 -> 45198.4 | C2: ='NAICS HOURLY INCOME'!C2*2080 -> 60777.6 | D2: ='NAICS HOURLY INCOME'!D2*2080 -> 39832 | E2: ='NAICS HOURLY INCOME'!E2*2080 -> 36316.8 | F2: ='NAICS HOURLY INCOME'!F2*2080 -> 38043.2 | G2: ='NAICS HOURLY INCOME'!G2*2080 -> 22256 | H2: ='NAICS HOURLY INCOME'!H2*2080 -> 39124.8 | ... T2: ='NAICS HOURLY INCOME'!T2*2080 -> 45697.6 | U2: 2010 | V2: National
A3: ='NAICS HOURLY INCOME'!A3*2080 -> 19468.8 | B3: ='NAICS HOURLY INCOME'!B3*2080 -> 46092.8 | C3: ='NAICS HOURLY INCOME'!C3*2080 -> 62608 | D3: ='NAICS HOURLY INCOME'!D3*2080 -> 40684.8 | E3: ='NAICS HOURLY INCOME'!E3*2080 -> 36982.4 | F3: ='NAICS HOURLY INCOME'!F3*2080 -> 38708.8 | G3: ='NAICS HOURLY INCOME'!G3*2080 -> 22630.4 | H3: ='NAICS HOURLY INCOME'!H3*2080 -> 40164.8 | ... T3: ='NAICS HOURLY INCOME'!T3*2080 -> 46529.6 | U3: 2011 | V3: National
A4: ='NAICS HOURLY INCOME'!A4*2080 -> 19552 | B4: ='NAICS HOURLY INCOME'!B4*2080 -> 47569.6 | C4: ='NAICS HOURLY INCOME'!C4*2080 -> 63897.6 | D4: ='NAICS HOURLY INCOME'!D4*2080 -> 41308.8 | E4: ='NAICS HOURLY INCOME'!E4*2080 -> 37398.4 | F4: ='NAICS HOURLY INCOME'!F4*2080 -> 39228.8 | G4: ='NAICS HOURLY INCOME'!G4*2080 -> 22755.2 | H4: ='NAICS HOURLY INCOME'!H4*2080 -> 40414.4 | ... T4: ='NAICS HOURLY INCOME'!T4*2080 -> 46966.4 | U4: 2012 | V4: National
A5: ='NAICS HOURLY INCOME'!A5*2080 -> 19614.4 | B5: ='NAICS HOURLY INCOME'!B5*2080 -> 47985.6 | C5: ='NAICS HOURLY INCOME'!C5*2080 -> 66040 | D5: ='NAICS HOURLY INCOME'!D5*2080 -> 41828.8 | E5: ='NAICS HOURLY INCOME'!E5*2080 -> 37689.6 | F5: ='NAICS HOURLY INCOME'!F5*2080 -> 39686.4 | G5: ='NAICS HOURLY INCOME'!G5*2080 -> 22984 | H5: ='NAICS HOURLY INCOME'!H5*2080 -> 40123.2 | ... T5: ='NAICS HOURLY INCOME'!T5*2080 -> 47569.6 | U5: 2013 | V5: National
A6: ='NAICS HOURLY INCOME'!A6*2080 -> 20176 | B6: ='NAICS HOURLY INCOME'!B6*2080 -> 49004.8 | C6: ='NAICS HOURLY INCOME'!C6*2080 -> 68182.4 | D6: ='NAICS HOURLY INCOME'!D6*2080 -> 42348.8 | E6: ='NAICS HOURLY INCOME'!E6*2080 -> 38147.2 | F6: ='NAICS HOURLY INCOME'!F6*2080 -> 40123.2 | G6: ='NAICS HOURLY INCOME'!G6*2080 -> 23275.2 | H6: ='NAICS HOURLY INCOME'!H6*2080 -> 40518.4 | ... T6: ='NAICS HOURLY INCOME'!T6*2080 -> 48859.2 | U6: 2014 | V6: National
A7: ='NAICS HOURLY INCOME'!A7*2080 -> 21881.6 | B7: ='NAICS HOURLY INCOME'!B7*2080 -> 49566.4 | C7: ='NAICS HOURLY INCOME'!C7*2080 -> 70012.8 | D7: ='NAICS HOURLY INCOME'!D7*2080 -> 43347.2 | E7: ='NAICS HOURLY INCOME'!E7*2080 -> 38708.8 | F7: ='NAICS HOURLY INCOME'!F7*2080 -> 40976 | G7: ='NAICS HOURLY INCOME'!G7*2080 -> 23670.4 | H7: ='NAICS HOURLY INCOME'!H7*2080 -> 40164.8 | ... T7: ='NAICS HOURLY INCOME'!T7*2080 -> 49566.4 | U7: 2015 | V7: National
A8: ='NAICS HOURLY INCOME'!A8*2080 -> 23628.8 | B8: ='NAICS HOURLY INCOME'!B8*2080 -> 52270.4 | C8: ='NAICS HOURLY INCOME'!C8*2080 -> 72300.8 | D8: ='NAICS HOURLY INCOME'!D8*2080 -> 44636.8 | E8: ='NAICS HOURLY INCOME'!E8*2080 -> 39520 | F8: ='NAICS HOURLY INCOME'!F8*2080 -> 42078.4 | G8: ='NAICS HOURLY INCOME'!G8*2080 -> 24252.8 | H8: ='NAICS HOURLY INCOME'!H8*2080 -> 40352 | ... T8: ='NAICS HOURLY INCOME'!T8*2080 -> 50668.8 | U8: 2016 | V8: National
A9: ='NAICS HOURLY INCOME'!A9*2080 -> 24481.6 | B9: ='NAICS HOURLY INCOME'!B9*2080 -> 51667.2 | C9: ='NAICS HOURLY INCOME'!C9*2080 -> 73944 | D9: ='NAICS HOURLY INCOME'!D9*2080 -> 45822.4 | E9: ='NAICS HOURLY INCOME'!E9*2080 -> 40268.8 | F9: ='NAICS HOURLY INCOME'!F9*2080 -> 42910.4 | G9: ='NAICS HOURLY INCOME'!G9*2080 -> 24876.8 | H9: ='NAICS HOURLY INCOME'!H9*2080 -> 40955.2 | ... T9: ='NAICS HOURLY INCOME'!T9*2080 -> 51688 | U9: 2017 | V9: National
A10: ='NAICS HOURLY INCOME'!A10*2080 -> 25500.8 | B10: ='NAICS HOURLY INCOME'!B10*2080 -> 52083.2 | C10: ='NAICS HOURLY INCOME'!C10*2080 -> 75899.2 | D10: ='NAICS HOURLY INCOME'!D10*2080 -> 47278.4 | E10: ='NAICS HOURLY INCOME'!E10*2080 -> 41350.4 | F10: ='NAICS HOURLY INCOME'!F10*2080 -> 43825.6 | G10: ='NAICS HOURLY INCOME'!G10*2080 -> 25792 | H10: ='NAICS HOURLY INCOME'!H10*2080 -> 41953.6 | ... T10: ='NAICS HOURLY INCOME'!T10*2080 -> 53185.6 | U10: 2018 | V10: National
A11: ='NAICS HOURLY INCOME'!A11*2080 -> 27414.4 | B11: ='NAICS HOURLY INCOME'!B11*2080 -> 52915.2 | C11: ='NAICS HOURLY INCOME'!C11*2080 -> 78000 | D11: ='NAICS HOURLY INCOME'!D11*2080 -> 49025.6 | E11: ='NAICS HOURLY INCOME'!E11*2080 -> 42556.8 | F11: ='NAICS HOURLY INCOME'!F11*2080 -> 45177.6 | G11: ='NAICS HOURLY INCOME'!G11*2080 -> 27372.8 | H11: ='NAICS HOURLY INCOME'!H11*2080 -> 42806.4 | ... T11: ='NAICS HOURLY INCOME'!T11*2080 -> 54516.8 | U11: 2019 | V11: National
A12: ='NAICS HOURLY INCOME'!A12*2080 -> 30014.4 | B12: ='NAICS HOURLY INCOME'!B12*2080 -> 54932.8 | C12: ='NAICS HOURLY INCOME'!C12*2080 -> 80641.6 | D12: ='NAICS HOURLY INCOME'!D12*2080 -> 50460.8 | E12: ='NAICS HOURLY INCOME'!E12*2080 -> 44096 | F12: ='NAICS HOURLY INCOME'!F12*2080 -> 46820.8 | G12: ='NAICS HOURLY INCOME'!G12*2080 -> 29057.6 | H12: ='NAICS HOURLY INCOME'!H12*2080 -> 43596.8 | ... T12: ='NAICS HOURLY INCOME'!T12*2080 -> 56617.6 | U12: 2020 | V12: National
A13: ='NAICS HOURLY INCOME'!A13*2080 -> 30014.4 | B13: ='NAICS HOURLY INCOME'!B13*2080 -> 59924.8 | C13: ='NAICS HOURLY INCOME'!C13*2080 -> 82222.4 | D13: ='NAICS HOURLY INCOME'!D13*2080 -> 49067.2 | E13: ='NAICS HOURLY INCOME'!E13*2080 -> 46820.8 | F13: ='NAICS HOURLY INCOME'!F13*2080 -> 47777.6 | G13: ='NAICS HOURLY INCOME'!G13*2080 -> 29868.8 | H13: ='NAICS HOURLY INCOME'!H13*2080 -> 46737.6 | ... T13: ='NAICS HOURLY INCOME'!T13*2080 -> 60132.8 | U13: 2021 | V13: National
A14: ='NAICS HOURLY INCOME'!A14*2080 -> 34028.8 | B14: ='NAICS HOURLY INCOME'!B14*2080 -> 59280 | C14: ='NAICS HOURLY INCOME'!C14*2080 -> 91998.4 | D14: ='NAICS HOURLY INCOME'!D14*2080 -> 54537.6 | E14: ='NAICS HOURLY INCOME'!E14*2080 -> 47611.2 | F14: ='NAICS HOURLY INCOME'!F14*2080 -> 49795.2 | G14: ='NAICS HOURLY INCOME'!G14*2080 -> 33259.2 | H14: ='NAICS HOURLY INCOME'!H14*2080 -> 47424 | ... T14: ='NAICS HOURLY INCOME'!T14*2080 -> 61068.8 | U14: 2022 | V14: National
A15: ='NAICS HOURLY INCOME'!A15*2080 -> 25679.696 | B15: ='NAICS HOURLY INCOME'!B15*2080 -> 59490.384 | C15: ='NAICS HOURLY INCOME'!C15*2080 -> 79995.813 | D15: ='NAICS HOURLY INCOME'!D15*2080 -> 52427.099 | E15: ='NAICS HOURLY INCOME'!E15*2080 -> 47800.373 | F15: ='NAICS HOURLY INCOME'!F15*2080 -> 50072.67 | G15: ='NAICS HOURLY INCOME'!G15*2080 -> 29293.47 | H15: ='NAICS HOURLY INCOME'!H15*2080 -> 51496.278 | ... T15: ='NAICS HOURLY INCOME'!T15*2080 -> 60147.434 | U15: 2010 | V15: New York-Newark-Jersey City, NY-NJ-PA | W15: 35620
A16: ='NAICS HOURLY INCOME'!A16*2080 -> 25639.377 | B16: ='NAICS HOURLY INCOME'!B16*2080 -> 60701.773 | C16: ='NAICS HOURLY INCOME'!C16*2080 -> 82451.415 | D16: ='NAICS HOURLY INCOME'!D16*2080 -> 53579.724 | E16: ='NAICS HOURLY INCOME'!E16*2080 -> 48703.859 | F16: ='NAICS HOURLY INCOME'!F16*2080 -> 50977.436 | G16: ='NAICS HOURLY INCOME'!G16*2080 -> 29803.036 | H16: ='NAICS HOURLY INCOME'!H16*2080 -> 52894.911 | ... T16: ='NAICS HOURLY INCOME'!T16*2080 -> 61277.015 | U16: 2011 | V16: New York-Newark-Jersey City, NY-NJ-PA | W16: 35620
A17: ='NAICS HOURLY INCOME'!A17*2080 -> 25640.123 | B17: ='NAICS HOURLY INCOME'!B17*2080 -> 62381.873 | C17: ='NAICS HOURLY INCOME'!C17*2080 -> 83794.103 | D17: ='NAICS HOURLY INCOME'!D17*2080 -> 54171.579 | E17: ='NAICS HOURLY INCOME'!E17*2080 -> 49043.554 | F17: ='NAICS HOURLY INCOME'!F17*2080 -> 51443.906 | G17: ='NAICS HOURLY INCOME'!G17*2080 -> 29840.739 | H17: ='NAICS HOURLY INCOME'!H17*2080 -> 52998.679 | ... T17: ='NAICS HOURLY INCOME'!T17*2080 -> 61590.848 | U17: 2012 | V17: New York-Newark-Jersey City, NY-NJ-PA | W17: 35620
A18: ='NAICS HOURLY INCOME'!A18*2080 -> 25756.283 | B18: ='NAICS HOURLY INCOME'!B18*2080 -> 63011.394 | C18: ='NAICS HOURLY INCOME'!C18*2080 -> 86719.192 | D18: ='NAICS HOURLY INCOME'!D18*2080 -> 54926.707 | E18: ='NAICS HOURLY INCOME'!E18*2080 -> 49491.394 | F18: ='NAICS HOURLY INCOME'!F18*2080 -> 52113.455 | G18: ='NAICS HOURLY INCOME'!G18*2080 -> 30181.01 | H18: ='NAICS HOURLY INCOME'!H18*2080 -> 52687.03 | ... T18: ='NAICS HOURLY INCOME'!T18*2080 -> 62465.131 | U18: 2013 | V18: New York-Newark-Jersey City, NY-NJ-PA | W18: 35620
A19: ='NAICS HOURLY INCOME'!A19*2080 -> 26336.706 | B19: ='NAICS HOURLY INCOME'!B19*2080 -> 63968.33 | C19: ='NAICS HOURLY INCOME'!C19*2080 -> 89001.777 | D19: ='NAICS HOURLY INCOME'!D19*2080 -> 55279.932 | E19: ='NAICS HOURLY INCOME'!E19*2080 -> 49795.381 | F19: ='NAICS HOURLY INCOME'!F19*2080 -> 52374.749 | G19: ='NAICS HOURLY INCOME'!G19*2080 -> 30382.242 | H19: ='NAICS HOURLY INCOME'!H19*2080 -> 52890.623 | ... T19: ='NAICS HOURLY INCOME'!T19*2080 -> 63778.272 | U19: 2014 | V19: New York-Newark-Jersey City, NY-NJ-PA | W19: 35620
A20: ='NAICS HOURLY INCOME'!A20*2080 -> 28251.518 | B20: ='NAICS HOURLY INCOME'!B20*2080 -> 63995.596 | C20: ='NAICS HOURLY INCOME'!C20*2080 -> 90394.114 | D20: ='NAICS HOURLY INCOME'!D20*2080 -> 55965.934 | E20: ='NAICS HOURLY INCOME'!E20*2080 -> 49977.257 | F20: ='NAICS HOURLY INCOME'!F20*2080 -> 52904.458 | G20: ='NAICS HOURLY INCOME'!G20*2080 -> 30561.052 | H20: ='NAICS HOURLY INCOME'!H20*2080 -> 51857.111 | ... T20: ='NAICS HOURLY INCOME'!T20*2080 -> 63995.596 | U20: 2015 | V20: New York-Newark-Jersey City, NY-NJ-PA | W20: 35620
A21: ='NAICS HOURLY INCOME'!A21*2080 -> 30504.163 | B21: ='NAICS HOURLY INCOME'!B21*2080 -> 67479.721 | C21: ='NAICS HOURLY INCOME'!C21*2080 -> 93338.444 | D21: ='NAICS HOURLY INCOME'!D21*2080 -> 57624.943 | E21: ='NAICS HOURLY INCOME'!E21*2080 -> 51019.287 | F21: ='NAICS HOURLY INCOME'!F21*2080 -> 54322.115 | G21: ='NAICS HOURLY INCOME'!G21*2080 -> 31309.731 | H21: ='NAICS HOURLY INCOME'!H21*2080 -> 52093.378 | ... T21: ='NAICS HOURLY INCOME'!T21*2080 -> 65412.097 | U21: 2016 | V21: New York-Newark-Jersey City, NY-NJ-PA | W21: 35620
A22: ='NAICS HOURLY INCOME'!A22*2080 -> 31468.195 | B22: ='NAICS HOURLY INCOME'!B22*2080 -> 66412.062 | C22: ='NAICS HOURLY INCOME'!C22*2080 -> 95046.248 | D22: ='NAICS HOURLY INCOME'!D22*2080 -> 58899.264 | E22: ='NAICS HOURLY INCOME'!E22*2080 -> 51760.77 | F22: ='NAICS HOURLY INCOME'!F22*2080 -> 55156.233 | G22: ='NAICS HOURLY INCOME'!G22*2080 -> 31976.178 | H22: ='NAICS HOURLY INCOME'!H22*2080 -> 52643.056 | ... T22: ='NAICS HOURLY INCOME'!T22*2080 -> 66438.798 | U22: 2017 | V22: New York-Newark-Jersey City, NY-NJ-PA | W22: 35620
A23: ='NAICS HOURLY INCOME'!A23*2080 -> 32673.351 | B23: ='NAICS HOURLY INCOME'!B23*2080 -> 66732.521 | C23: ='NAICS HOURLY INCOME'!C23*2080 -> 97247.192 | D23: ='NAICS HOURLY INCOME'!D23*2080 -> 60576.286 | E23: ='NAICS HOURLY INCOME'!E23*2080 -> 52980.931 | F23: ='NAICS HOURLY INCOME'!F23*2080 -> 56152.325 | G23: ='NAICS HOURLY INCOME'!G23*2080 -> 33046.456 | H23: ='NAICS HOURLY INCOME'!H23*2080 -> 53753.792 | ... T23: ='NAICS HOURLY INCOME'!T23*2080 -> 68144.991 | U23: 2018 | V23: New York-Newark-Jersey City, NY-NJ-PA | W23: 35620
A24: ='NAICS HOURLY INCOME'!A24*2080 -> 35270.691 | B24: ='NAICS HOURLY INCOME'!B24*2080 -> 68079.392 | C24: ='NAICS HOURLY INCOME'!C24*2080 -> 100352.88 | D24: ='NAICS HOURLY INCOME'!D24*2080 -> 63075.128 | E24: ='NAICS HOURLY INCOME'!E24*2080 -> 54752.53 | F24: ='NAICS HOURLY INCOME'!F24*2080 -> 58124.386 | G24: ='NAICS HOURLY INCOME'!G24*2080 -> 35217.17 | H24: ='NAICS HOURLY INCOME'!H24*2080 -> 55073.659 | ... T24: ='NAICS HOURLY INCOME'!T24*2080 -> 70139.971 | U24: 2019 | V24: New York-Newark-Jersey City, NY-NJ-PA | W24: 35620
A25: ='NAICS HOURLY INCOME'!A25*2080 -> 39117.256 | B25: ='NAICS HOURLY INCOME'!B25*2080 -> 71592.982 | C25: ='NAICS HOURLY INCOME'!C25*2080 -> 105098.82 | D25: ='NAICS HOURLY INCOME'!D25*2080 -> 65764.701 | E25: ='NAICS HOURLY INCOME'!E25*2080 -> 57469.565 | F25: ='NAICS HOURLY INCOME'!F25*2080 -> 61020.751 | G25: ='NAICS HOURLY INCOME'!G25*2080 -> 37870.275 | H25: ='NAICS HOURLY INCOME'!H25*2080 -> 56818.967 | ... T25: ='NAICS HOURLY INCOME'!T25*2080 -> 73788.753 | U25: 2020 | V25: New York-Newark-Jersey City, NY-NJ-PA | W25: 35620
A26: ='NAICS HOURLY INCOME'!A26*2080 -> 42450.519 | B26: ='NAICS HOURLY INCOME'!B26*2080 -> 84753.947 | C26: ='NAICS HOURLY INCOME'!C26*2080 -> 116290.3 | D26: ='NAICS HOURLY INCOME'!D26*2080 -> 69397.627 | E26: ='NAICS HOURLY INCOME'!E26*2080 -> 66220.457 | F26: ='NAICS HOURLY INCOME'!F26*2080 -> 67573.696 | G26: ='NAICS HOURLY INCOME'!G26*2080 -> 42244.592 | H26: ='NAICS HOURLY INCOME'!H26*2080 -> 66102.784 | ... T26: ='NAICS HOURLY INCOME'!T26*2080 -> 85048.13 | U26: 2021 | V26: New York-Newark-Jersey City, NY-NJ-PA | W26: 35620
A27: ='NAICS HOURLY INCOME'!A27*2080 -> 43830.747 | B27: ='NAICS HOURLY INCOME'!B27*2080 -> 76355.518 | C27: ='NAICS HOURLY INCOME'!C27*2080 -> 118498.41 | D27: ='NAICS HOURLY INCOME'!D27*2080 -> 70247.077 | E27: ='NAICS HOURLY INCOME'!E27*2080 -> 61325.537 | F27: ='NAICS HOURLY INCOME'!F27*2080 -> 64138.635 | G27: ='NAICS HOURLY INCOME'!G27*2080 -> 42839.464 | H27: ='NAICS HOURLY INCOME'!H27*2080 -> 61084.415 | ... T27: ='NAICS HOURLY INCOME'!T27*2080 -> 78659.579 | U27: 2022 | V27: New York-Newark-Jersey City, NY-NJ-PA | W27: 35620

Sheet Index
A1: Year | B1: NYC Metro Median | C1: National Median | D1: Index
A2: 2022 | B2: 27.59 | C2: 21.42 | D2: =B2/C2 -> 1.2880486
A3: 2021 | B3: 26.83 | C3: 18.97 | D3: =B3/C3 -> 1.4143384
A4: 2020 | B4: 25.01 | C4: 19.19 | D4: =B4/C4 -> 1.303283
A5: 2019 | B5: 23.48 | C5: 18.25 | D5: =B5/C5 -> 1.2865753
A6: 2018 | B6: 22.64 | C6: 17.67 | D6: =B6/C6 -> 1.2812677
A7: 2017 | B7: 22.07 | C7: 17.17 | D7: =B7/C7 -> 1.2853815
A8: 2016 | B8: 21.74 | C8: 16.84 | D8: =B8/C8 -> 1.2909739
A9: 2015 | B9: 21.2 | C9: 16.42 | D9: =B9/C9 -> 1.2911084
A10: 2014 | B10: 20.99 | C10: 16.08 | D10: =B10/C10 -> 1.3053483
A11: 2013 | B11: 20.8 | C11: 15.84 | D11: =B11/C11 -> 1.3131313
A12: 2012 | B12: 20.51 | C12: 15.64 | D12: =B12/C12 -> 1.3113811
A13: 2011 | B13: 20.36 | C13: 15.46 | D13: =B13/C13 -> 1.316947
A14: 2010 | B14: 19.98 | C14: 15.18 | D14: =B14/C14 -> 1.3162055

Sheet National_NAICS
A1: CNS Code | B1: NAICS Sector | C1: Sector Name | D1: Macro-Sector | E1: Med-Hourly 2010 | F1: Med-Annually 2010 | G1: Med-Hourly 2011 | H1: Med-Annually 2011 | I1: Med-Hourly 2012 | J1: Med-Annually 2012 | K1: Med-Hourly 2013 | L1: Med-Annually 2013 | M1: Med-Hourly 2014 | N1: Med-Annually 2014 | O1: Med-Hourly 2015 | P1: Med-Annually 2015 | Q1: Med-Hourly 2016 | R1: Med-Annually 2016 | S1: Med-Hourly 2017 | T1: Med-Annually 2017 | U1: Med-Hourly 2018 | V1: Med-Annually 2018 | W1: Med-Hourly 2019 | X1: Med-Annually 2019 | Y1: Med-Hourly 2020 | Z1: Med-Annually 2020 | AA1: Med-Hourly 2021 | AB1: Med-Annually 2021 | AC1: Med-Hourly 2022 | AD1: Med-Annually 2022
A2: CNS01 | B2: 11 | C2: Agriculture, Forestry, Fishing, and Hunting | D2: Agri-Mining | E2: 9.38 | F2: =E2*2080 -> 19510.4 | G2: 9.36 | H2: =G2*2080 -> 19468.8 | I2: 9.4 | J2: =I2*2080 -> 19552 | K2: 9.43 | L2: =K2*2080 -> 19614.4 | M2: 9.7 | N2: =M2*2080 -> 20176 | O2: 10.52 | P2: =O2*2080 -> 21881.6 | Q2: 11.36 | R2: =Q2*2080 -> 23628.8 | S2: 11.77 | T2: =S2*2080 -> 24481.6 | U2: 12.26 | V2: =U2*2080 -> 25500.8 | W2: 13.18 | X2: =W2*2080 -> 27414.4 | Y2: 14.43 | Z2: =Y2*2080 -> 30014.4 | AA2: 14.43 | AB2: =AA2*2080 -> 30014.4 | AC2: 16.36 | AD2: =AC2*2080 -> 34028.8
A3: CNS02 | B3: 21 | C3: Mining, Quarrying, and Oil & Gas Extraction | D3: Agri-Mining | E3: 21.73 | F3: =E3*2080 -> 45198.4 | G3: 22.16 | H3: =G3*2080 -> 46092.8 | I3: 22.87 | J3: =I3*2080 -> 47569.6 | K3: 23.07 | L3: =K3*2080 -> 47985.6 | M3: 23.56 | N3: =M3*2080 -> 49004.8 | O3: 23.83 | P3: =O3*2080 -> 49566.4 | Q3: 25.13 | R3: =Q3*2080 -> 52270.4 | S3: 24.84 | T3: =S3*2080 -> 51667.2 | U3: 25.04 | V3: =U3*2080 -> 52083.2 | W3: 25.44 | X3: =W3*2080 -> 52915.2 | Y3: 26.41 | Z3: =Y3*2080 -> 54932.8 | AA3: 28.81 | AB3: =AA3*2080 -> 59924.8 | AC3: 28.5 | AD3: =AC3*2080 -> 59280
A4: CNS03 | B4: 22 | C4: Utilities | D4: Industrial | E4: 29.22 | F4: =E4*2080 -> 60777.6 | G4: 30.1 | H4: =G4*2080 -> 62608 | I4: 30.72 | J4: =I4*2080 -> 63897.6 | K4: 31.75 | L4: =K4*2080 -> 66040 | M4: 32.78 | N4: =M4*2080 -> 68182.4 | O4: 33.66 | P4: =O4*2080 -> 70012.8 | Q4: 34.76 | R4: =Q4*2080 -> 72300.8 | S4: 35.55 | T4: =S4*2080 -> 73944 | U4: 36.49 | V4: =U4*2080 -> 75899.2 | W4: 37.5 | X4: =W4*2080 -> 78000 | Y4: 38.77 | Z4: =Y4*2080 -> 80641.6 | AA4: 39.53 | AB4: =AA4*2080 -> 82222.4 | AC4: 44.23 | AD4: =AC4*2080 -> 91998.4
A5: CNS04 | B5: 23 | C5: Construction | D5: Industrial | E5: 19.15 | F5: =E5*2080 -> 39832 | G5: 19.56 | H5: =G5*2080 -> 40684.8 | I5: 19.86 | J5: =I5*2080 -> 41308.8 | K5: 20.11 | L5: =K5*2080 -> 41828.8 | M5: 20.36 | N5: =M5*2080 -> 42348.8 | O5: 20.84 | P5: =O5*2080 -> 43347.2 | Q5: 21.46 | R5: =Q5*2080 -> 44636.8 | S5: 22.03 | T5: =S5*2080 -> 45822.4 | U5: 22.73 | V5: =U5*2080 -> 47278.4 | W5: 23.57 | X5: =W5*2080 -> 49025.6 | Y5: 24.26 | Z5: =Y5*2080 -> 50460.8 | AA5: 23.59 | AB5: =AA5*2080 -> 49067.2 | AC5: 26.22 | AD5: =AC5*2080 -> 54537.6
A6: CNS05 | B6: 31–33 | C6: Manufacturing | D6: Industrial | E6: 17.46 | F6: =E6*2080 -> 36316.8 | G6: 17.78 | H6: =G6*2080 -> 36982.4 | I6: 17.98 | J6: =I6*2080 -> 37398.4 | K6: 18.12 | L6: =K6*2080 -> 37689.6 | M6: 18.34 | N6: =M6*2080 -> 38147.2 | O6: 18.61 | P6: =O6*2080 -> 38708.8 | Q6: 19 | R6: =Q6*2080 -> 39520 | S6: 19.36 | T6: =S6*2080 -> 40268.8 | U6: 19.88 | V6: =U6*2080 -> 41350.4 | W6: 20.46 | X6: =W6*2080 -> 42556.8 | Y6: 21.2 | Z6: =Y6*2080 -> 44096 | AA6: 22.51 | AB6: =AA6*2080 -> 46820.8 | AC6: 22.89 | AD6: =AC6*2080 -> 47611.2
A7: CNS06 | B7: 42 | C7: Wholesale Trade | D7: Industrial | E7: 18.29 | F7: =E7*2080 -> 38043.2 | G7: 18.61 | H7: =G7*2080 -> 38708.8 | I7: 18.86 | J7: =I7*2080 -> 39228.8 | K7: 19.08 | L7: =K7*2080 -> 39686.4 | M7: 19.29 | N7: =M7*2080 -> 40123.2 | O7: 19.7 | P7: =O7*2080 -> 40976 | Q7: 20.23 | R7: =Q7*2080 -> 42078.4 | S7: 20.63 | T7: =S7*2080 -> 42910.4 | U7: 21.07 | V7: =U7*2080 -> 43825.6 | W7: 21.72 | X7: =W7*2080 -> 45177.6 | Y7: 22.51 | Z7: =Y7*2080 -> 46820.8 | AA7: 22.97 | AB7: =AA7*2080 -> 47777.6 | AC7: 23.94 | AD7: =AC7*2080 -> 49795.2
A8: CNS07 | B8: 44–45 | C8: Retail Trade | D8: Local Services | E8: 10.7 | F8: =E8*2080 -> 22256 | G8: 10.88 | H8: =G8*2080 -> 22630.4 | I8: 10.94 | J8: =I8*2080 -> 22755.2 | K8: 11.05 | L8: =K8*2080 -> 22984 | M8: 11.19 | N8: =M8*2080 -> 23275.2 | O8: 11.38 | P8: =O8*2080 -> 23670.4 | Q8: 11.66 | R8: =Q8*2080 -> 24252.8 | S8: 11.96 | T8: =S8*2080 -> 24876.8 | U8: 12.4 | V8: =U8*2080 -> 25792 | W8: 13.16 | X8: =W8*2080 -> 27372.8 | Y8: 13.97 | Z8: =Y8*2080 -> 29057.6 | AA8: 14.36 | AB8: =AA8*2080 -> 29868.8 | AC8: 15.99 | AD8: =AC8*2080 -> 33259.2
A9: CNS08 | B9: 48–49 | C9: Transportation and Warehousing | D9: Industrial | E9: 18.81 | F9: =E9*2080 -> 39124.8 | G9: 19.31 | H9: =G9*2080 -> 40164.8 | I9: 19.43 | J9: =I9*2080 -> 40414.4 | K9: 19.29 | L9: =K9*2080 -> 40123.2 | M9: 19.48 | N9: =M9*2080 -> 40518.4 | O9: 19.31 | P9: =O9*2080 -> 40164.8 | Q9: 19.4 | R9: =Q9*2080 -> 40352 | S9: 19.69 | T9: =S9*2080 -> 40955.2 | U9: 20.17 | V9: =U9*2080 -> 41953.6 | W9: 20.58 | X9: =W9*2080 -> 42806.4 | Y9: 20.96 | Z9: =Y9*2080 -> 43596.8 | AA9: 22.47 | AB9: =AA9*2080 -> 46737.6 | AC9: 22.8 | AD9: =AC9*2080 -> 47424
A10: CNS09 | B10: 51 | C10: Information | D10: Office | E10: 24.17 | F10: =E10*2080 -> 50273.6 | G10: 24.93 | H10: =G10*2080 -> 51854.4 | I10: 25.57 | J10: =I10*2080 -> 53185.6 | K10: 26.12 | L10: =K10*2080 -> 54329.6 | M10: 26.81 | N10: =M10*2080 -> 55764.8 | O10: 27.82 | P10: =O10*2080 -> 57865.6 | Q10: 28.55 | R10: =Q10*2080 -> 59384 | S10: 29.51 | T10: =S10*2080 -> 61380.8 | U10: 30.49 | V10: =U10*2080 -> 63419.2 | W10: 31.66 | X10: =W10*2080 -> 65852.8 | Y10: 34.2 | Z10: =Y10*2080 -> 71136 | AA10: 37.02 | AB10: =AA10*2080 -> 77001.6 | AC10: 38.45 | AD10: =AC10*2080 -> 79976
A11: CNS10 | B11: 52 | C11: Finance and Insurance | D11: Office | E11: 20.65 | F11: =E11*2080 -> 42952 | G11: 21.35 | H11: =G11*2080 -> 44408 | I11: 21.78 | J11: =I11*2080 -> 45302.4 | K11: 22.3 | L11: =K11*2080 -> 46384 | M11: 22.86 | N11: =M11*2080 -> 47548.8 | O11: 23.6 | P11: =O11*2080 -> 49088 | Q11: 24.41 | R11: =Q11*2080 -> 50772.8 | S11: 25.1 | T11: =S11*2080 -> 52208 | U11: 25.89 | V11: =U11*2080 -> 53851.2 | W11: 27.01 | X11: =W11*2080 -> 56180.8 | Y11: 28.04 | Z11: =Y11*2080 -> 58323.2 | AA11: 29.44 | AB11: =AA11*2080 -> 61235.2 | AC11: 30.42 | AD11: =AC11*2080 -> 63273.6
A12: CNS11 | B12: 53 | C12: Real Estate and Rental and Leasing | D12: Office | E12: 14.98 | F12: =E12*2080 -> 31158.4 | G12: 15.3 | H12: =G12*2080 -> 31824 | I12: 15.52 | J12: =I12*2080 -> 32281.6 | K12: 15.83 | L12: =K12*2080 -> 32926.4 | M12: 16.28 | N12: =M12*2080 -> 33862.4 | O12: 16.74 | P12: =O12*2080 -> 34819.2 | Q12: 17.24 | R12: =Q12*2080 -> 35859.2 | S12: 17.71 | T12: =S12*2080 -> 36836.8 | U12: 18.41 | V12: =U12*2080 -> 38292.8 | W12: 19.02 | X12: =W12*2080 -> 39561.6 | Y12: 19.69 | Z12: =Y12*2080 -> 40955.2 | AA12: 21.36 | AB12: =AA12*2080 -> 44428.8 | AC12: 22.21 | AD12: =AC12*2080 -> 46196.8
A13: CNS12 | B13: 54 | C13: Professional, Scientific, and Technical Services | D13: Office | E13: 27.07 | F13: =E13*2080 -> 56305.6 | G13: 27.87 | H13: =G13*2080 -> 57969.6 | I13: 28.43 | J13: =I13*2080 -> 59134.4 | K13: 29 | L13: =K13*2080 -> 60320 | M13: 29.45 | N13: =M13*2080 -> 61256 | O13: 30.12 | P13: =O13*2080 -> 62649.6 | Q13: 30.82 | R13: =Q13*2080 -> 64105.6 | S13: 31.43 | T13: =S13*2080 -> 65374.4 | U13: 32.32 | V13: =U13*2080 -> 67225.6 | W13: 33.5 | X13: =W13*2080 -> 69680 | Y13: 34.86 | Z13: =Y13*2080 -> 72508.8 | AA13: 36.98 | AB13: =AA13*2080 -> 76918.4 | AC13: 37.77 | AD13: =AC13*2080 -> 78561.6
A14: CNS13 | B14: 55 | C14: Management of Companies and Enterprises | D14: Office | E14: 26.78 | F14: =E14*2080 -> 55702.4 | G14: 27.84 | H14: =G14*2080 -> 57907.2 | I14: 28.52 | J14: =I14*2080 -> 59321.6 | K14: 29.08 | L14: =K14*2080 -> 60486.4 | M14: 29.91 | N14: =M14*2080 -> 62212.8 | O14: 30.59 | P14: =O14*2080 -> 63627.2 | Q14: 31.43 | R14: =Q14*2080 -> 65374.4 | S14: 32.06 | T14: =S14*2080 -> 66684.8 | U14: 33.18 | V14: =U14*2080 -> 69014.4 | W14: 34.23 | X14: =W14*2080 -> 71198.4 | Y14: 35.61 | Z14: =Y14*2080 -> 74068.8 | AA14: 37.38 | AB14: =AA14*2080 -> 77750.4 | AC14: 38.71 | AD14: =AC14*2080 -> 80516.8
A15: CNS14 | B15: 56 | C15: Administrative and Support, Waste Management and Remediation Services | D15: Local Services | E15: 12.67 | F15: =E15*2080 -> 26353.6 | G15: 12.8 | H15: =G15*2080 -> 26624 | I15: 12.74 | J15: =I15*2080 -> 26499.2 | K15: 12.96 | L15: =K15*2080 -> 26956.8 | M15: 13.15 | N15: =M15*2080 -> 27352 | O15: 13.43 | P15: =O15*2080 -> 27934.4 | Q15: 13.88 | R15: =Q15*2080 -> 28870.4 | S15: 14.28 | T15: =S15*2080 -> 29702.4 | U15: 14.84 | V15: =U15*2080 -> 30867.2 | W15: 15.48 | X15: =W15*2080 -> 32198.4 | Y15: 16.29 | Z15: =Y15*2080 -> 33883.2 | AA15: 17.48 | AB15: =AA15*2080 -> 36358.4 | AC15: 17.75 | AD15: =AC15*2080 -> 36920
A16: CNS15 | B16: 61 | C16: Educational Services | D16: Institutional | E16: 20.73 | F16: =E16*2080 -> 43118.4 | G16: 21.03 | H16: =G16*2080 -> 43742.4 | I16: 21.1 | J16: =I16*2080 -> 43888 | K16: 21.22 | L16: =K16*2080 -> 44137.6 | M16: 21.51 | N16: =M16*2080 -> 44740.8 | O16: 21.89 | P16: =O16*2080 -> 45531.2 | Q16: 22.46 | R16: =Q16*2080 -> 46716.8 | S16: 22.88 | T16: =S16*2080 -> 47590.4 | U16: 23.48 | V16: =U16*2080 -> 48838.4 | W16: 24.11 | X16: =W16*2080 -> 50148.8 | Y16: 24.85 | Z16: =Y16*2080 -> 51688 | AA16: 24.1 | AB16: =AA16*2080 -> 50128 | AC16: 26.49 | AD16: =AC16*2080 -> 55099.2
A17: CNS16 | B17: 62 | C17: Health Care and Social Assistance | D17: Institutional | E17: 16.33 | F17: =E17*2080 -> 33966.4 | G17: 16.73 | H17: =G17*2080 -> 34798.4 | I17: 16.94 | J17: =I17*2080 -> 35235.2 | K17: 17.16 | L17: =K17*2080 -> 35692.8 | M17: 17.38 | N17: =M17*2080 -> 36150.4 | O17: 17.72 | P17: =O17*2080 -> 36857.6 | Q17: 18.11 | R17: =Q17*2080 -> 37668.8 | S17: 18.16 | T17: =S17*2080 -> 37772.8 | U17: 18.56 | V17: =U17*2080 -> 38604.8 | W17: 18.99 | X17: =W17*2080 -> 39499.2 | Y17: 19.6 | Z17: =Y17*2080 -> 40768 | AA17: 20.23 | AB17: =AA17*2080 -> 42078.4 | AC17: 21.59 | AD17: =AC17*2080 -> 44907.2
A18: CNS17 | B18: 71 | C18: Arts, Entertainment, and Recreation | D18: Local Services | E18: 11.22 | F18: =E18*2080 -> 23337.6 | G18: 11.29 | H18: =G18*2080 -> 23483.2 | I18: 11.39 | J18: =I18*2080 -> 23691.2 | K18: 11.49 | L18: =K18*2080 -> 23899.2 | M18: 11.68 | N18: =M18*2080 -> 24294.4 | O18: 11.99 | P18: =O18*2080 -> 24939.2 | Q18: 12.3 | R18: =Q18*2080 -> 25584 | S18: 12.66 | T18: =S18*2080 -> 26332.8 | U18: 13.19 | V18: =U18*2080 -> 27435.2 | W18: 13.88 | X18: =W18*2080 -> 28870.4 | Y18: 14.72 | Z18: =Y18*2080 -> 30617.6 | AA18: 14.7 | AB18: =AA18*2080 -> 30576 | AC18: 16.72 | AD18: =AC18*2080 -> 34777.6
A19: CNS18 | B19: 72 | C19: Accommodation and Food Services | D19: Local Services | E19: 9.05 | F19: =E19*2080 -> 18824 | G19: 9.14 | H19: =G19*2080 -> 19011.2 | I19: 9.18 | J19: =I19*2080 -> 19094.4 | K19: 9.22 | L19: =K19*2080 -> 19177.6 | M19: 9.3 | N19: =M19*2080 -> 19344 | O19: 9.49 | P19: =O19*2080 -> 19739.2 | Q19: 10.01 | R19: =Q19*2080 -> 20820.8 | S19: 10.57 | T19: =S19*2080 -> 21985.6 | U19: 11.12 | V19: =U19*2080 -> 23129.6 | W19: 11.64 | X19: =W19*2080 -> 24211.2 | Y19: 12.19 | Z19: =Y19*2080 -> 25355.2 | AA19: 13.69 | AB19: =AA19*2080 -> 28475.2 | AC19: 14.31 | AD19: =AC19*2080 -> 29764.8
A20: CNS19 | B20: 81 | C20: Other Services (except Public Administration) | D20: Local Services | E20: 13.24 | F20: =E20*2080 -> 27539.2 | G20: 13.38 | H20: =G20*2080 -> 27830.4 | I20: 13.54 | J20: =I20*2080 -> 28163.2 | K20: 13.69 | L20: =K20*2080 -> 28475.2 | M20: 13.99 | N20: =M20*2080 -> 29099.2 | O20: 14.3 | P20: =O20*2080 -> 29744 | Q20: 14.69 | R20: =Q20*2080 -> 30555.2 | S20: 15.03 | T20: =S20*2080 -> 31262.4 | U20: 15.59 | V20: =U20*2080 -> 32427.2 | W20: 16.33 | X20: =W20*2080 -> 33966.4 | Y20: 17.5 | Z20: =Y20*2080 -> 36400 | AA20: 18.02 | AB20: =AA20*2080 -> 37481.6 | AC20: 18.88 | AD20: =AC20*2080 -> 39270.4
A21: CNS20 | B21: 92 | C21: Public Administration | D21: Institutional | E21: 21.97 | F21: =E21*2080 -> 45697.6 | G21: 22.37 | H21: =G21*2080 -> 46529.6 | I21: 22.58 | J21: =I21*2080 -> 46966.4 | K21: 22.87 | L21: =K21*2080 -> 47569.6 | M21: 23.49 | N21: =M21*2080 -> 48859.2 | O21: 23.83 | P21: =O21*2080 -> 49566.4 | Q21: 24.36 | R21: =Q21*2080 -> 50668.8 | S21: 24.85 | T21: =S21*2080 -> 51688 | U21: 25.57 | V21: =U21*2080 -> 53185.6 | W21: 26.21 | X21: =W21*2080 -> 54516.8 | Y21: 27.22 | Z21: =Y21*2080 -> 56617.6 | AA21: 28.91 | AB21: =AA21*2080 -> 60132.8 | AC21: 29.36 | AD21: =AC21*2080 -> 61068.8

Sheet MSA_NAICS
A1: CNS Code | B1: NAICS Sector | C1: Sector Name | D1: Macro-Sector | E1: MSA Med-Hourly 2010 | F1: MSA Med-Annually 2010 | G1: MSA Med-Hourly 2011 | H1: MSA Med-Annually 2011 | I1: MSA Med-Hourly 2012 | J1: MSA Med-Annually 2012 | K1: MSA Med-Hourly 2013 | L1: MSA Med-Annually 2013 | M1: MSA Med-Hourly 2014 | N1: MSA Med-Annually 2014 | O1: MSA Med-Hourly 2015 | P1: MSA Med-Annually 2015 | Q1: MSA Med-Hourly 2016 | R1: MSA Med-Annually 2016 | S1: MSA Med-Hourly 2017 | T1: MSA Med-Annually 2017 | U1: MSA Med-Hourly 2018 | V1: MSA Med-Annually 2018 | W1: MSA Med-Hourly 2019 | X1: MSA Med-Annually 2019 | Y1: MSA Med-Hourly 2020 | Z1: MSA Med-Annually 2020 | AA1: MSA Med-Hourly 2021 | AB1: MSA Med-Annually 2021 | AC1: MSA Med-Hourly 2022 | AD1: MSA Med-Annually 2022
A2: CNS01 | B2: 11 | C2: Agriculture, Forestry, Fishing, and Hunting | D2: Agri-Mining | E2: =National_NAICS!E2*Index!$D$14 -> 12.346008 | F2: =E2*2080 -> 25679.696 | G2: =National_NAICS!G2*Index!$D$13 -> 12.326624 | H2: =G2*2080 -> 25639.377 | I2: =National_NAICS!I2*Index!$D$12 -> 12.326982 | J2: =I2*2080 -> 25640.123 | K2: =National_NAICS!K2*Index!$D$11 -> 12.382828 | L2: =K2*2080 -> 25756.283 | M2: =National_NAICS!M2*Index!$D$10 -> 12.661878 | N2: =M2*2080 -> 26336.706 | O2: =National_NAICS!O2*Index!$D$9 -> 13.58246 | P2: =O2*2080 -> 28251.518 | Q2: =National_NAICS!Q2*Index!$D$8 -> 14.665463 | R2: =Q2*2080 -> 30504.163 | S2: =National_NAICS!S2*Index!$D$7 -> 15.12894 | T2: =S2*2080 -> 31468.195 | U2: =National_NAICS!U2*Index!$D$6 -> 15.708342 | V2: =U2*2080 -> 32673.351 | W2: =National_NAICS!W2*Index!$D$5 -> 16.957063 | X2: =W2*2080 -> 35270.691 | Y2: =National_NAICS!Y2*Index!$D$4 -> 18.806373 | Z2: =Y2*2080 -> 39117.256 | AA2: =National_NAICS!AA2*Index!$D$3 -> 20.408904 | AB2: =AA2*2080 -> 42450.519 | AC2: =National_NAICS!AC2*Index!$D$2 -> 21.072474 | AD2: =AC2*2080 -> 43830.747
A3: CNS02 | B3: 21 | C3: Mining, Quarrying, and Oil & Gas Extraction | D3: Agri-Mining | E3: =National_NAICS!E3*Index!$D$14 -> 28.601146 | F3: =E3*2080 -> 59490.384 | G3: =National_NAICS!G3*Index!$D$13 -> 29.183545 | H3: =G3*2080 -> 60701.773 | I3: =National_NAICS!I3*Index!$D$12 -> 29.991285 | J3: =I3*2080 -> 62381.873 | K3: =National_NAICS!K3*Index!$D$11 -> 30.293939 | L3: =K3*2080 -> 63011.394 | M3: =National_NAICS!M3*Index!$D$10 -> 30.754005 | N3: =M3*2080 -> 63968.33 | O3: =National_NAICS!O3*Index!$D$9 -> 30.767113 | P3: =O3*2080 -> 63995.596 | Q3: =National_NAICS!Q3*Index!$D$8 -> 32.442173 | R3: =Q3*2080 -> 67479.721 | S3: =National_NAICS!S3*Index!$D$7 -> 31.928876 | T3: =S3*2080 -> 66412.062 | U3: =National_NAICS!U3*Index!$D$6 -> 32.082943 | V3: =U3*2080 -> 66732.521 | W3: =National_NAICS!W3*Index!$D$5 -> 32.730477 | X3: =W3*2080 -> 68079.392 | Y3: =National_NAICS!Y3*Index!$D$4 -> 34.419703 | Z3: =Y3*2080 -> 71592.982 | AA3: =National_NAICS!AA3*Index!$D$3 -> 40.74709 | AB3: =AA3*2080 -> 84753.947 | AC3: =National_NAICS!AC3*Index!$D$2 -> 36.709384 | AD3: =AC3*2080 -> 76355.518
A4: CNS03 | B4: 22 | C4: Utilities | D4: Industrial | E4: =National_NAICS!E4*Index!$D$14 -> 38.459526 | F4: =E4*2080 -> 79995.813 | G4: =National_NAICS!G4*Index!$D$13 -> 39.640103 | H4: =G4*2080 -> 82451.415 | I4: =National_NAICS!I4*Index!$D$12 -> 40.285627 | J4: =I4*2080 -> 83794.103 | K4: =National_NAICS!K4*Index!$D$11 -> 41.691919 | L4: =K4*2080 -> 86719.192 | M4: =National_NAICS!M4*Index!$D$10 -> 42.789316 | N4: =M4*2080 -> 89001.777 | O4: =National_NAICS!O4*Index!$D$9 -> 43.458709 | P4: =O4*2080 -> 90394.114 | Q4: =National_NAICS!Q4*Index!$D$8 -> 44.874252 | R4: =Q4*2080 -> 93338.444 | S4: =National_NAICS!S4*Index!$D$7 -> 45.695312 | T4: =S4*2080 -> 95046.248 | U4: =National_NAICS!U4*Index!$D$6 -> 46.753458 | V4: =U4*2080 -> 97247.192 | W4: =National_NAICS!W4*Index!$D$5 -> 48.246575 | X4: =W4*2080 -> 100352.88 | Y4: =National_NAICS!Y4*Index!$D$4 -> 50.52828 | Z4: =Y4*2080 -> 105098.82 | AA4: =National_NAICS!AA4*Index!$D$3 -> 55.908798 | AB4: =AA4*2080 -> 116290.3 | AC4: =National_NAICS!AC4*Index!$D$2 -> 56.970387 | AD4: =AC4*2080 -> 118498.41
A5: CNS04 | B5: 23 | C5: Construction | D5: Industrial | E5: =National_NAICS!E5*Index!$D$14 -> 25.205336 | F5: =E5*2080 -> 52427.099 | G5: =National_NAICS!G5*Index!$D$13 -> 25.759483 | H5: =G5*2080 -> 53579.724 | I5: =National_NAICS!I5*Index!$D$12 -> 26.044028 | J5: =I5*2080 -> 54171.579 | K5: =National_NAICS!K5*Index!$D$11 -> 26.407071 | L5: =K5*2080 -> 54926.707 | M5: =National_NAICS!M5*Index!$D$10 -> 26.576891 | N5: =M5*2080 -> 55279.932 | O5: =National_NAICS!O5*Index!$D$9 -> 26.906699 | P5: =O5*2080 -> 55965.934 | Q5: =National_NAICS!Q5*Index!$D$8 -> 27.704299 | R5: =Q5*2080 -> 57624.943 | S5: =National_NAICS!S5*Index!$D$7 -> 28.316954 | T5: =S5*2080 -> 58899.264 | U5: =National_NAICS!U5*Index!$D$6 -> 29.123214 | V5: =U5*2080 -> 60576.286 | W5: =National_NAICS!W5*Index!$D$5 -> 30.324581 | X5: =W5*2080 -> 63075.128 | Y5: =National_NAICS!Y5*Index!$D$4 -> 31.617645 | Z5: =Y5*2080 -> 65764.701 | AA5: =National_NAICS!AA5*Index!$D$3 -> 33.364244 | AB5: =AA5*2080 -> 69397.627 | AC5: =National_NAICS!AC5*Index!$D$2 -> 33.772633 | AD5: =AC5*2080 -> 70247.077
A6: CNS05 | B6: 31–33 | C6: Manufacturing | D6: Industrial | E6: =National_NAICS!E6*Index!$D$14 -> 22.980949 | F6: =E6*2080 -> 47800.373 | G6: =National_NAICS!G6*Index!$D$13 -> 23.415317 | H6: =G6*2080 -> 48703.859 | I6: =National_NAICS!I6*Index!$D$12 -> 23.578632 | J6: =I6*2080 -> 49043.554 | K6: =National_NAICS!K6*Index!$D$11 -> 23.793939 | L6: =K6*2080 -> 49491.394 | M6: =National_NAICS!M6*Index!$D$10 -> 23.940087 | N6: =M6*2080 -> 49795.381 | O6: =National_NAICS!O6*Index!$D$9 -> 24.027527 | P6: =O6*2080 -> 49977.257 | Q6: =National_NAICS!Q6*Index!$D$8 -> 24.528504 | R6: =Q6*2080 -> 51019.287 | S6: =National_NAICS!S6*Index!$D$7 -> 24.884985 | T6: =S6*2080 -> 51760.77 | U6: =National_NAICS!U6*Index!$D$6 -> 25.471602 | V6: =U6*2080 -> 52980.931 | W6: =National_NAICS!W6*Index!$D$5 -> 26.323332 | X6: =W6*2080 -> 54752.53 | Y6: =National_NAICS!Y6*Index!$D$4 -> 27.629599 | Z6: =Y6*2080 -> 57469.565 | AA6: =National_NAICS!AA6*Index!$D$3 -> 31.836758 | AB6: =AA6*2080 -> 66220.457 | AC6: =National_NAICS!AC6*Index!$D$2 -> 29.483431 | AD6: =AC6*2080 -> 61325.537
A7: CNS06 | B7: 42 | C7: Wholesale Trade | D7: Industrial | E7: =National_NAICS!E7*Index!$D$14 -> 24.073399 | F7: =E7*2080 -> 50072.67 | G7: =National_NAICS!G7*Index!$D$13 -> 24.508383 | H7: =G7*2080 -> 50977.436 | I7: =National_NAICS!I7*Index!$D$12 -> 24.732647 | J7: =I7*2080 -> 51443.906 | K7: =National_NAICS!K7*Index!$D$11 -> 25.054545 | L7: =K7*2080 -> 52113.455 | M7: =National_NAICS!M7*Index!$D$10 -> 25.180168 | N7: =M7*2080 -> 52374.749 | O7: =National_NAICS!O7*Index!$D$9 -> 25.434836 | P7: =O7*2080 -> 52904.458 | Q7: =National_NAICS!Q7*Index!$D$8 -> 26.116401 | R7: =Q7*2080 -> 54322.115 | S7: =National_NAICS!S7*Index!$D$7 -> 26.51742 | T7: =S7*2080 -> 55156.233 | U7: =National_NAICS!U7*Index!$D$6 -> 26.99631 | V7: =U7*2080 -> 56152.325 | W7: =National_NAICS!W7*Index!$D$5 -> 27.944416 | X7: =W7*2080 -> 58124.386 | Y7: =National_NAICS!Y7*Index!$D$4 -> 29.336899 | Z7: =Y7*2080 -> 61020.751 | AA7: =National_NAICS!AA7*Index!$D$3 -> 32.487354 | AB7: =AA7*2080 -> 67573.696 | AC7: =National_NAICS!AC7*Index!$D$2 -> 30.835882 | AD7: =AC7*2080 -> 64138.635
A8: CNS07 | B8: 44–45 | C8: Retail Trade | D8: Local Services | E8: =National_NAICS!E8*Index!$D$14 -> 14.083399 | F8: =E8*2080 -> 29293.47 | G8: =National_NAICS!G8*Index!$D$13 -> 14.328383 | H8: =G8*2080 -> 29803.036 | I8: =National_NAICS!I8*Index!$D$12 -> 14.346509 | J8: =I8*2080 -> 29840.739 | K8: =National_NAICS!K8*Index!$D$11 -> 14.510101 | L8: =K8*2080 -> 30181.01 | M8: =National_NAICS!M8*Index!$D$10 -> 14.606847 | N8: =M8*2080 -> 30382.242 | O8: =National_NAICS!O8*Index!$D$9 -> 14.692814 | P8: =O8*2080 -> 30561.052 | Q8: =National_NAICS!Q8*Index!$D$8 -> 15.052755 | R8: =Q8*2080 -> 31309.731 | S8: =National_NAICS!S8*Index!$D$7 -> 15.373162 | T8: =S8*2080 -> 31976.178 | U8: =National_NAICS!U8*Index!$D$6 -> 15.887719 | V8: =U8*2080 -> 33046.456 | W8: =National_NAICS!W8*Index!$D$5 -> 16.931332 | X8: =W8*2080 -> 35217.17 | Y8: =National_NAICS!Y8*Index!$D$4 -> 18.206863 | Z8: =Y8*2080 -> 37870.275 | AA8: =National_NAICS!AA8*Index!$D$3 -> 20.3099 | AB8: =AA8*2080 -> 42244.592 | AC8: =National_NAICS!AC8*Index!$D$2 -> 20.595896 | AD8: =AC8*2080 -> 42839.464
A9: CNS08 | B9: 48–49 | C9: Transportation and Warehousing | D9: Industrial | E9: =National_NAICS!E9*Index!$D$14 -> 24.757826 | F9: =E9*2080 -> 51496.278 | G9: =National_NAICS!G9*Index!$D$13 -> 25.430246 | H9: =G9*2080 -> 52894.911 | I9: =National_NAICS!I9*Index!$D$12 -> 25.480134 | J9: =I9*2080 -> 52998.679 | K9: =National_NAICS!K9*Index!$D$11 -> 25.330303 | L9: =K9*2080 -> 52687.03 | M9: =National_NAICS!M9*Index!$D$10 -> 25.428184 | N9: =M9*2080 -> 52890.623 | O9: =National_NAICS!O9*Index!$D$9 -> 24.931303 | P9: =O9*2080 -> 51857.111 | Q9: =National_NAICS!Q9*Index!$D$8 -> 25.044893 | R9: =Q9*2080 -> 52093.378 | S9: =National_NAICS!S9*Index!$D$7 -> 25.309161 | T9: =S9*2080 -> 52643.056 | U9: =National_NAICS!U9*Index!$D$6 -> 25.843169 | V9: =U9*2080 -> 53753.792 | W9: =National_NAICS!W9*Index!$D$5 -> 26.477721 | X9: =W9*2080 -> 55073.659 | Y9: =National_NAICS!Y9*Index!$D$4 -> 27.316811 | Z9: =Y9*2080 -> 56818.967 | AA9: =National_NAICS!AA9*Index!$D$3 -> 31.780185 | AB9: =AA9*2080 -> 66102.784 | AC9: =National_NAICS!AC9*Index!$D$2 -> 29.367507 | AD9: =AC9*2080 -> 61084.415
A10: CNS09 | B10: 51 | C10: Information | D10: Office | E10: =National_NAICS!E10*Index!$D$14 -> 31.812688 | F10: =E10*2080 -> 66170.391 | G10: =National_NAICS!G10*Index!$D$13 -> 32.831488 | H10: =G10*2080 -> 68289.494 | I10: =National_NAICS!I10*Index!$D$12 -> 33.532014 | J10: =I10*2080 -> 69746.589 | K10: =National_NAICS!K10*Index!$D$11 -> 34.29899 | L10: =K10*2080 -> 71341.899 | M10: =National_NAICS!M10*Index!$D$10 -> 34.996387 | N10: =M10*2080 -> 72792.485 | O10: =National_NAICS!O10*Index!$D$9 -> 35.918636 | P10: =O10*2080 -> 74710.762 | Q10: =National_NAICS!Q10*Index!$D$8 -> 36.857304 | R10: =Q10*2080 -> 76663.192 | S10: =National_NAICS!S10*Index!$D$7 -> 37.931607 | T10: =S10*2080 -> 78897.744 | U10: =National_NAICS!U10*Index!$D$6 -> 39.065852 | V10: =U10*2080 -> 81256.972 | W10: =National_NAICS!W10*Index!$D$5 -> 40.732975 | X10: =W10*2080 -> 84724.589 | Y10: =National_NAICS!Y10*Index!$D$4 -> 44.572277 | Z10: =Y10*2080 -> 92710.337 | AA10: =National_NAICS!AA10*Index!$D$3 -> 52.358809 | AB10: =AA10*2080 -> 108906.32 | AC10: =National_NAICS!AC10*Index!$D$2 -> 49.525467 | AD10: =AC10*2080 -> 103012.97
A11: CNS10 | B11: 52 | C11: Finance and Insurance | D11: Office | E11: =National_NAICS!E11*Index!$D$14 -> 27.179644 | F11: =E11*2080 -> 56533.66 | G11: =National_NAICS!G11*Index!$D$13 -> 28.116818 | H11: =G11*2080 -> 58482.981 | I11: =National_NAICS!I11*Index!$D$12 -> 28.56188 | J11: =I11*2080 -> 59408.71 | K11: =National_NAICS!K11*Index!$D$11 -> 29.282828 | L11: =K11*2080 -> 60908.283 | M11: =National_NAICS!M11*Index!$D$10 -> 29.840261 | N11: =M11*2080 -> 62067.743 | O11: =National_NAICS!O11*Index!$D$9 -> 30.470158 | P11: =O11*2080 -> 63377.929 | Q11: =National_NAICS!Q11*Index!$D$8 -> 31.512672 | R11: =Q11*2080 -> 65546.358 | S11: =National_NAICS!S11*Index!$D$7 -> 32.263075 | T11: =S11*2080 -> 67107.196 | U11: =National_NAICS!U11*Index!$D$6 -> 33.17202 | V11: =U11*2080 -> 68997.802 | W11: =National_NAICS!W11*Index!$D$5 -> 34.7504 | X11: =W11*2080 -> 72280.832 | Y11: =National_NAICS!Y11*Index!$D$4 -> 36.544054 | Z11: =Y11*2080 -> 76011.633 | AA11: =National_NAICS!AA11*Index!$D$3 -> 41.638123 | AB11: =AA11*2080 -> 86607.297 | AC11: =National_NAICS!AC11*Index!$D$2 -> 39.182437 | AD11: =AC11*2080 -> 81499.469
A12: CNS11 | B12: 53 | C12: Real Estate and Rental and Leasing | D12: Office | E12: =National_NAICS!E12*Index!$D$14 -> 19.716759 | F12: =E12*2080 -> 41010.858 | G12: =National_NAICS!G12*Index!$D$13 -> 20.149288 | H12: =G12*2080 -> 41910.52 | I12: =National_NAICS!I12*Index!$D$12 -> 20.352634 | J12: =I12*2080 -> 42333.479 | K12: =National_NAICS!K12*Index!$D$11 -> 20.786869 | L12: =K12*2080 -> 43236.687 | M12: =National_NAICS!M12*Index!$D$10 -> 21.25107 | N12: =M12*2080 -> 44202.225 | O12: =National_NAICS!O12*Index!$D$9 -> 21.613155 | P12: =O12*2080 -> 44955.362 | Q12: =National_NAICS!Q12*Index!$D$8 -> 22.25639 | R12: =Q12*2080 -> 46293.29 | S12: =National_NAICS!S12*Index!$D$7 -> 22.764106 | T12: =S12*2080 -> 47349.34 | U12: =National_NAICS!U12*Index!$D$6 -> 23.588138 | V12: =U12*2080 -> 49063.327 | W12: =National_NAICS!W12*Index!$D$5 -> 24.470663 | X12: =W12*2080 -> 50898.979 | Y12: =National_NAICS!Y12*Index!$D$4 -> 25.661641 | Z12: =Y12*2080 -> 53376.214 | AA12: =National_NAICS!AA12*Index!$D$3 -> 30.210269 | AB12: =AA12*2080 -> 62837.359 | AC12: =National_NAICS!AC12*Index!$D$2 -> 28.607558 | AD12: =AC12*2080 -> 59503.721
A13: CNS12 | B13: 54 | C13: Professional, Scientific, and Technical Services | D13: Office | E13: =National_NAICS!E13*Index!$D$14 -> 35.629684 | F13: =E13*2080 -> 74109.742 | G13: =National_NAICS!G13*Index!$D$13 -> 36.703312 | H13: =G13*2080 -> 76342.888 | I13: =National_NAICS!I13*Index!$D$12 -> 37.282564 | J13: =I13*2080 -> 77547.733 | K13: =National_NAICS!K13*Index!$D$11 -> 38.080808 | L13: =K13*2080 -> 79208.081 | M13: =National_NAICS!M13*Index!$D$10 -> 38.442506 | N13: =M13*2080 -> 79960.413 | O13: =National_NAICS!O13*Index!$D$9 -> 38.888185 | P13: =O13*2080 -> 80887.425 | Q13: =National_NAICS!Q13*Index!$D$8 -> 39.787815 | R13: =Q13*2080 -> 82758.655 | S13: =National_NAICS!S13*Index!$D$7 -> 40.39954 | T13: =S13*2080 -> 84031.043 | U13: =National_NAICS!U13*Index!$D$6 -> 41.410572 | V13: =U13*2080 -> 86133.989 | W13: =National_NAICS!W13*Index!$D$5 -> 43.100274 | X13: =W13*2080 -> 89648.57 | Y13: =National_NAICS!Y13*Index!$D$4 -> 45.432444 | Z13: =Y13*2080 -> 94499.483 | AA13: =National_NAICS!AA13*Index!$D$3 -> 52.302235 | AB13: =AA13*2080 -> 108788.65 | AC13: =National_NAICS!AC13*Index!$D$2 -> 48.649594 | AD13: =AC13*2080 -> 101191.16
A14: CNS13 | B14: 55 | C14: Management of Companies and Enterprises | D14: Office | E14: =National_NAICS!E14*Index!$D$14 -> 35.247984 | F14: =E14*2080 -> 73315.807 | G14: =National_NAICS!G14*Index!$D$13 -> 36.663803 | H14: =G14*2080 -> 76260.711 | I14: =National_NAICS!I14*Index!$D$12 -> 37.400588 | J14: =I14*2080 -> 77793.224 | K14: =National_NAICS!K14*Index!$D$11 -> 38.185859 | L14: =K14*2080 -> 79426.586 | M14: =National_NAICS!M14*Index!$D$10 -> 39.042966 | N14: =M14*2080 -> 81209.37 | O14: =National_NAICS!O14*Index!$D$9 -> 39.495006 | P14: =O14*2080 -> 82149.613 | Q14: =National_NAICS!Q14*Index!$D$8 -> 40.575309 | R14: =Q14*2080 -> 84396.642 | S14: =National_NAICS!S14*Index!$D$7 -> 41.20933 | T14: =S14*2080 -> 85715.407 | U14: =National_NAICS!U14*Index!$D$6 -> 42.512462 | V14: =U14*2080 -> 88425.921 | W14: =National_NAICS!W14*Index!$D$5 -> 44.039474 | X14: =W14*2080 -> 91602.106 | Y14: =National_NAICS!Y14*Index!$D$4 -> 46.409906 | Z14: =Y14*2080 -> 96532.605 | AA14: =National_NAICS!AA14*Index!$D$3 -> 52.86797 | AB14: =AA14*2080 -> 109965.38 | AC14: =National_NAICS!AC14*Index!$D$2 -> 49.860359 | AD14: =AC14*2080 -> 103709.55
A15: CNS14 | B15: 56 | C15: Administrative and Support, Waste Management and Remediation Services | D15: Local Services | E15: =National_NAICS!E15*Index!$D$14 -> 16.676324 | F15: =E15*2080 -> 34686.754 | G15: =National_NAICS!G15*Index!$D$13 -> 16.856921 | H15: =G15*2080 -> 35062.396 | I15: =National_NAICS!I15*Index!$D$12 -> 16.706995 | J15: =I15*2080 -> 34750.549 | K15: =National_NAICS!K15*Index!$D$11 -> 17.018182 | L15: =K15*2080 -> 35397.818 | M15: =National_NAICS!M15*Index!$D$10 -> 17.16533 | N15: =M15*2080 -> 35703.886 | O15: =National_NAICS!O15*Index!$D$9 -> 17.339586 | P15: =O15*2080 -> 36066.339 | Q15: =National_NAICS!Q15*Index!$D$8 -> 17.918717 | R15: =Q15*2080 -> 37270.932 | S15: =National_NAICS!S15*Index!$D$7 -> 18.355248 | T15: =S15*2080 -> 38178.915 | U15: =National_NAICS!U15*Index!$D$6 -> 19.014012 | V15: =U15*2080 -> 39549.146 | W15: =National_NAICS!W15*Index!$D$5 -> 19.916186 | X15: =W15*2080 -> 41425.668 | Y15: =National_NAICS!Y15*Index!$D$4 -> 21.230479 | Z15: =Y15*2080 -> 44159.397 | AA15: =National_NAICS!AA15*Index!$D$3 -> 24.722636 | AB15: =AA15*2080 -> 51423.082 | AC15: =National_NAICS!AC15*Index!$D$2 -> 22.862862 | AD15: =AC15*2080 -> 47554.753
A16: CNS15 | B16: 61 | C16: Educational Services | D16: Institutional | E16: =National_NAICS!E16*Index!$D$14 -> 27.284941 | F16: =E16*2080 -> 56752.677 | G16: =National_NAICS!G16*Index!$D$13 -> 27.695395 | H16: =G16*2080 -> 57606.421 | I16: =National_NAICS!I16*Index!$D$12 -> 27.670141 | J16: =I16*2080 -> 57553.893 | K16: =National_NAICS!K16*Index!$D$11 -> 27.864646 | L16: =K16*2080 -> 57958.465 | M16: =National_NAICS!M16*Index!$D$10 -> 28.078041 | N16: =M16*2080 -> 58402.325 | O16: =National_NAICS!O16*Index!$D$9 -> 28.262363 | P16: =O16*2080 -> 58785.715 | Q16: =National_NAICS!Q16*Index!$D$8 -> 28.995273 | R16: =Q16*2080 -> 60310.168 | S16: =National_NAICS!S16*Index!$D$7 -> 29.409528 | T16: =S16*2080 -> 61171.819 | U16: =National_NAICS!U16*Index!$D$6 -> 30.084165 | V16: =U16*2080 -> 62575.064 | W16: =National_NAICS!W16*Index!$D$5 -> 31.019332 | X16: =W16*2080 -> 64520.21 | Y16: =National_NAICS!Y16*Index!$D$4 -> 32.386582 | Z16: =Y16*2080 -> 67364.09 | AA16: =National_NAICS!AA16*Index!$D$3 -> 34.085556 | AB16: =AA16*2080 -> 70897.957 | AC16: =National_NAICS!AC16*Index!$D$2 -> 34.120406 | AD16: =AC16*2080 -> 70970.445
A17: CNS16 | B17: 62 | C17: Health Care and Social Assistance | D17: Institutional | E17: =National_NAICS!E17*Index!$D$14 -> 21.493636 | F17: =E17*2080 -> 44706.764 | G17: =National_NAICS!G17*Index!$D$13 -> 22.032523 | H17: =G17*2080 -> 45827.647 | I17: =National_NAICS!I17*Index!$D$12 -> 22.214795 | J17: =I17*2080 -> 46206.774 | K17: =National_NAICS!K17*Index!$D$11 -> 22.533333 | L17: =K17*2080 -> 46869.333 | M17: =National_NAICS!M17*Index!$D$10 -> 22.686953 | N17: =M17*2080 -> 47188.862 | O17: =National_NAICS!O17*Index!$D$9 -> 22.878441 | P17: =O17*2080 -> 47587.157 | Q17: =National_NAICS!Q17*Index!$D$8 -> 23.379537 | R17: =Q17*2080 -> 48629.437 | S17: =National_NAICS!S17*Index!$D$7 -> 23.342528 | T17: =S17*2080 -> 48552.458 | U17: =National_NAICS!U17*Index!$D$6 -> 23.780328 | V17: =U17*2080 -> 49463.083 | W17: =National_NAICS!W17*Index!$D$5 -> 24.432066 | X17: =W17*2080 -> 50818.697 | Y17: =National_NAICS!Y17*Index!$D$4 -> 25.544346 | Z17: =Y17*2080 -> 53132.24 | AA17: =National_NAICS!AA17*Index!$D$3 -> 28.612066 | AB17: =AA17*2080 -> 59513.098 | AC17: =National_NAICS!AC17*Index!$D$2 -> 27.808968 | AD17: =AC17*2080 -> 57842.654
A18: CNS17 | B18: 71 | C18: Arts, Entertainment, and Recreation | D18: Local Services | E18: =National_NAICS!E18*Index!$D$14 -> 14.767826 | F18: =E18*2080 -> 30717.078 | G18: =National_NAICS!G18*Index!$D$13 -> 14.868331 | H18: =G18*2080 -> 30926.129 | I18: =National_NAICS!I18*Index!$D$12 -> 14.93663 | J18: =I18*2080 -> 31068.191 | K18: =National_NAICS!K18*Index!$D$11 -> 15.087879 | L18: =K18*2080 -> 31382.788 | M18: =National_NAICS!M18*Index!$D$10 -> 15.246468 | N18: =M18*2080 -> 31712.653 | O18: =National_NAICS!O18*Index!$D$9 -> 15.48039 | P18: =O18*2080 -> 32199.211 | Q18: =National_NAICS!Q18*Index!$D$8 -> 15.878979 | R18: =Q18*2080 -> 33028.276 | S18: =National_NAICS!S18*Index!$D$7 -> 16.27293 | T18: =S18*2080 -> 33847.693 | U18: =National_NAICS!U18*Index!$D$6 -> 16.899921 | V18: =U18*2080 -> 35151.835 | W18: =National_NAICS!W18*Index!$D$5 -> 17.857666 | X18: =W18*2080 -> 37143.945 | Y18: =National_NAICS!Y18*Index!$D$4 -> 19.184325 | Z18: =Y18*2080 -> 39903.396 | AA18: =National_NAICS!AA18*Index!$D$3 -> 20.790775 | AB18: =AA18*2080 -> 43244.812 | AC18: =National_NAICS!AC18*Index!$D$2 -> 21.536172 | AD18: =AC18*2080 -> 44795.237
A19: CNS18 | B19: 72 | C19: Accommodation and Food Services | D19: Local Services | E19: =National_NAICS!E19*Index!$D$14 -> 11.91166 | F19: =E19*2080 -> 24776.253 | G19: =National_NAICS!G19*Index!$D$13 -> 12.036895 | H19: =G19*2080 -> 25036.742 | I19: =National_NAICS!I19*Index!$D$12 -> 12.038478 | J19: =I19*2080 -> 25040.035 | K19: =National_NAICS!K19*Index!$D$11 -> 12.107071 | L19: =K19*2080 -> 25182.707 | M19: =National_NAICS!M19*Index!$D$10 -> 12.139739 | N19: =M19*2080 -> 25250.657 | O19: =National_NAICS!O19*Index!$D$9 -> 12.252619 | P19: =O19*2080 -> 25485.447 | Q19: =National_NAICS!Q19*Index!$D$8 -> 12.922648 | R19: =Q19*2080 -> 26879.109 | S19: =National_NAICS!S19*Index!$D$7 -> 13.586482 | T19: =S19*2080 -> 28259.883 | U19: =National_NAICS!U19*Index!$D$6 -> 14.247697 | V19: =U19*2080 -> 29635.209 | W19: =National_NAICS!W19*Index!$D$5 -> 14.975737 | X19: =W19*2080 -> 31149.533 | Y19: =National_NAICS!Y19*Index!$D$4 -> 15.887019 | Z19: =Y19*2080 -> 33045 | AA19: =National_NAICS!AA19*Index!$D$3 -> 19.362293 | AB19: =AA19*2080 -> 40273.57 | AC19: =National_NAICS!AC19*Index!$D$2 -> 18.431975 | AD19: =AC19*2080 -> 38338.508
A20: CNS19 | B20: 81 | C20: Other Services (except Public Administration) | D20: Local Services | E20: =National_NAICS!E20*Index!$D$14 -> 17.426561 | F20: =E20*2080 -> 36247.247 | G20: =National_NAICS!G20*Index!$D$13 -> 17.62075 | H20: =G20*2080 -> 36651.161 | I20: =National_NAICS!I20*Index!$D$12 -> 17.7561 | J20: =I20*2080 -> 36932.687 | K20: =National_NAICS!K20*Index!$D$11 -> 17.976768 | L20: =K20*2080 -> 37391.677 | M20: =National_NAICS!M20*Index!$D$10 -> 18.261822 | N20: =M20*2080 -> 37984.59 | O20: =National_NAICS!O20*Index!$D$9 -> 18.46285 | P20: =O20*2080 -> 38402.728 | Q20: =National_NAICS!Q20*Index!$D$8 -> 18.964406 | R20: =Q20*2080 -> 39445.965 | S20: =National_NAICS!S20*Index!$D$7 -> 19.319284 | T20: =S20*2080 -> 40184.11 | U20: =National_NAICS!U20*Index!$D$6 -> 19.974963 | V20: =U20*2080 -> 41547.923 | W20: =National_NAICS!W20*Index!$D$5 -> 21.009775 | X20: =W20*2080 -> 43700.333 | Y20: =National_NAICS!Y20*Index!$D$4 -> 22.807452 | Z20: =Y20*2080 -> 47439.5 | AA20: =National_NAICS!AA20*Index!$D$3 -> 25.486378 | AB20: =AA20*2080 -> 53011.667 | AC20: =National_NAICS!AC20*Index!$D$2 -> 24.318357 | AD20: =AC20*2080 -> 50582.182
A21: CNS20 | B21: 92 | C21: Public Administration | D21: Institutional | E21: =National_NAICS!E21*Index!$D$14 -> 28.917036 | F21: =E21*2080 -> 60147.434 | G21: =National_NAICS!G21*Index!$D$13 -> 29.460103 | H21: =G21*2080 -> 61277.015 | I21: =National_NAICS!I21*Index!$D$12 -> 29.610985 | J21: =I21*2080 -> 61590.848 | K21: =National_NAICS!K21*Index!$D$11 -> 30.031313 | L21: =K21*2080 -> 62465.131 | M21: =National_NAICS!M21*Index!$D$10 -> 30.662631 | N21: =M21*2080 -> 63778.272 | O21: =National_NAICS!O21*Index!$D$9 -> 30.767113 | P21: =O21*2080 -> 63995.596 | Q21: =National_NAICS!Q21*Index!$D$8 -> 31.448124 | R21: =Q21*2080 -> 65412.097 | S21: =National_NAICS!S21*Index!$D$7 -> 31.94173 | T21: =S21*2080 -> 66438.798 | U21: =National_NAICS!U21*Index!$D$6 -> 32.762015 | V21: =U21*2080 -> 68144.991 | W21: =National_NAICS!W21*Index!$D$5 -> 33.72114 | X21: =W21*2080 -> 70139.971 | Y21: =National_NAICS!Y21*Index!$D$4 -> 35.475362 | Z21: =Y21*2080 -> 73788.753 | AA21: =National_NAICS!AA21*Index!$D$3 -> 40.888524 | AB21: =AA21*2080 -> 85048.13 | AC21: =National_NAICS!AC21*Index!$D$2 -> 37.817106 | AD21: =AC21*2080 -> 78659.579

Sheet HUD Income Limit
A1: HUD Category | B1: 2010 | C1: 2011 | D1: 2012 | E1: 2013 | F1: 2014 | G1: 2015 | H1: 2016 | I1: 2017 | J1: 2018 | K1: 2019 | L1: 2020 | M1: 2021 | N1: 2022 | O1: AMI Percentage | P1: Meaning
A2: 30% LIMITS | B2: 16650 | C2: 17200 | D2: 17450 | E2: 18050 | F2: 17650 | G2: 18150 | H2: 19050 | I2: 20050 | J2: 21950 | K2: 22400 | L2: 23900 | M2: 25100 | N2: 28000 | O2: 30% AMI | P2: Extremely Low Income
A3: VERY LOW INCOME | B3: 27750 | C3: 28650 | D3: 29050 | E3: 30100 | F3: 29400 | G3: 30250 | H3: 31750 | I3: 33400 | J3: 36550 | K3: 37350 | L3: 39800 | M3: 41800 | N3: 46700 | O3: 50% AMI | P3: Very Low Income
A4: 60% LIMITS | B4: 33300 | C4: 34380 | D4: 34860 | E4: 36120 | F4: 35280 | G4: 36300 | H4: 38100 | I4: 40080 | J4: 43860 | K4: 44820 | L4: 47760 | M4: 50160 | N4: 56040 | O4: 60% AMI | P4: LIHTC Income Limit (Tax Credit Housing)
A5: LOW INCOME | B5: 44350 | C5: 45850 | D5: 46500 | E5: 48100 | F5: 47000 | G5: 48350 | H5: 50750 | I5: 53450 | J5: 58450 | K5: 59750 | L5: 63700 | M5: 66850 | N5: 74800 | O5: 80% AMI | P5: Low Income
